tests/large.in
1000
o
0 B 0 GOOG 999 1
1 B 1 GOOG 999 1
2 B 2 GOOG 999 2
3 B 3 GOOG 999 3
4 B 4 GOOG 999 4
5 B 5 GOOG 999 5
6 B 6 GOOG 999 6
7 B 7 GOOG 999 7
8 B 8 GOOG 999 8
9 B 9 GOOG 999 9
10 B 10 GOOG 999 10
11 B 11 GOOG 999 11
12 B 12 GOOG 999 12
13 B 13 GOOG 999 13
14 B 14 GOOG 999 14
15 B 15 GOOG 999 15
16 B 16 GOOG 999 16
17 B 17 GOOG 999 17
18 B 18 GOOG 999 18
19 B 19 GOOG 999 19
20 B 20 GOOG 999 20
21 B 21 GOOG 999 21
22 B 22 GOOG 999 22
23 B 23 GOOG 999 23
24 B 24 GOOG 999 24
25 B 25 GOOG 999 25
26 B 26 GOOG 999 26
27 B 27 GOOG 999 27
28 B 28 GOOG 999 28
29 B 29 GOOG 999 29
30 B 30 GOOG 999 30
31 B 31 GOOG 999 31
32 B 32 GOOG 999 32
33 B 33 GOOG 999 33
34 B 34 GOOG 999 34
35 B 35 GOOG 999 35
36 B 36 GOOG 999 36
37 B 37 GOOG 999 37
38 B 38 GOOG 999 38
39 B 39 GOOG 999 39
40 B 40 GOOG 999 40
41 B 41 GOOG 999 41
42 B 42 GOOG 999 42
43 B 43 GOOG 999 43
44 B 44 GOOG 999 44
45 B 45 GOOG 999 45
46 B 46 GOOG 999 46
47 B 47 GOOG 999 47
48 B 48 GOOG 999 48
49 B 49 GOOG 999 49
50 B 50 GOOG 999 50
51 B 51 GOOG 999 51
52 B 52 GOOG 999 52
53 B 53 GOOG 999 53
54 B 54 GOOG 999 54
55 B 55 GOOG 999 55
56 B 56 GOOG 999 56
57 B 57 GOOG 999 57
58 B 58 GOOG 999 58
59 B 59 GOOG 999 59
60 B 60 GOOG 999 60
61 B 61 GOOG 999 61
62 B 62 GOOG 999 62
63 B 63 GOOG 999 63
64 B 64 GOOG 999 64
65 B 65 GOOG 999 65
66 B 66 GOOG 999 66
67 B 67 GOOG 999 67
68 B 68 GOOG 999 68
69 B 69 GOOG 999 69
70 B 70 GOOG 999 70
71 B 71 GOOG 999 71
72 B 72 GOOG 999 72
73 B 73 GOOG 999 73
74 B 74 GOOG 999 74
75 B 75 GOOG 999 75
76 B 76 GOOG 999 76
77 B 77 GOOG 999 77
78 B 78 GOOG 999 78
79 B 79 GOOG 999 79
80 B 80 GOOG 999 80
81 B 81 GOOG 999 81
82 B 82 GOOG 999 82
83 B 83 GOOG 999 83
84 B 84 GOOG 999 84
85 B 85 GOOG 999 85
86 B 86 GOOG 999 86
87 B 87 GOOG 999 87
88 B 88 GOOG 999 88
89 B 89 GOOG 999 89
90 B 90 GOOG 999 90
91 B 91 GOOG 999 91
92 B 92 GOOG 999 92
93 B 93 GOOG 999 93
94 B 94 GOOG 999 94
95 B 95 GOOG 999 95
96 B 96 GOOG 999 96
97 B 97 GOOG 999 97
98 B 98 GOOG 999 98
99 B 99 GOOG 999 99
100 B 100 GOOG 999 100
101 B 101 GOOG 999 101
102 B 102 GOOG 999 102
103 B 103 GOOG 999 103
104 B 104 GOOG 999 104
105 B 105 GOOG 999 105
106 B 106 GOOG 999 106
107 B 107 GOOG 999 107
108 B 108 GOOG 999 108
109 B 109 GOOG 999 109
110 B 110 GOOG 999 110
111 B 111 GOOG 999 111
112 B 112 GOOG 999 112
113 B 113 GOOG 999 113
114 B 114 GOOG 999 114
115 B 115 GOOG 999 115
116 B 116 GOOG 999 116
117 B 117 GOOG 999 117
118 B 118 GOOG 999 118
119 B 119 GOOG 999 119
120 B 120 GOOG 999 120
121 B 121 GOOG 999 121
122 B 122 GOOG 999 122
123 B 123 GOOG 999 123
124 B 124 GOOG 999 124
125 B 125 GOOG 999 125
126 B 126 GOOG 999 126
127 B 127 GOOG 999 127
128 B 128 GOOG 999 128
129 B 129 GOOG 999 129
130 B 130 GOOG 999 130
131 B 131 GOOG 999 131
132 B 132 GOOG 999 132
133 B 133 GOOG 999 133
134 B 134 GOOG 999 134
135 B 135 GOOG 999 135
136 B 136 GOOG 999 136
137 B 137 GOOG 999 137
138 B 138 GOOG 999 138
139 B 139 GOOG 999 139
140 B 140 GOOG 999 140
141 B 141 GOOG 999 141
142 B 142 GOOG 999 142
143 B 143 GOOG 999 143
144 B 144 GOOG 999 144
145 B 145 GOOG 999 145
146 B 146 GOOG 999 146
147 B 147 GOOG 999 147
148 B 148 GOOG 999 148
149 B 149 GOOG 999 149
150 B 150 GOOG 999 150
151 B 151 GOOG 999 151
152 B 152 GOOG 999 152
153 B 153 GOOG 999 153
154 B 154 GOOG 999 154
155 B 155 GOOG 999 155
156 B 156 GOOG 999 156
157 B 157 GOOG 999 157
158 B 158 GOOG 999 158
159 B 159 GOOG 999 159
160 B 160 GOOG 999 160
161 B 161 GOOG 999 161
162 B 162 GOOG 999 162
163 B 163 GOOG 999 163
164 B 164 GOOG 999 164
165 B 165 GOOG 999 165
166 B 166 GOOG 999 166
167 B 167 GOOG 999 167
168 B 168 GOOG 999 168
169 B 169 GOOG 999 169
170 B 170 GOOG 999 170
171 B 171 GOOG 999 171
172 B 172 GOOG 999 172
173 B 173 GOOG 999 173
174 B 174 GOOG 999 174
175 B 175 GOOG 999 175
176 B 176 GOOG 999 176
177 B 177 GOOG 999 177
178 B 178 GOOG 999 178
179 B 179 GOOG 999 179
180 B 180 GOOG 999 180
181 B 181 GOOG 999 181
182 B 182 GOOG 999 182
183 B 183 GOOG 999 183
184 B 184 GOOG 999 184
185 B 185 GOOG 999 185
186 B 186 GOOG 999 186
187 B 187 GOOG 999 187
188 B 188 GOOG 999 188
189 B 189 GOOG 999 189
190 B 190 GOOG 999 190
191 B 191 GOOG 999 191
192 B 192 GOOG 999 192
193 B 193 GOOG 999 193
194 B 194 GOOG 999 194
195 B 195 GOOG 999 195
196 B 196 GOOG 999 196
197 B 197 GOOG 999 197
198 B 198 GOOG 999 198
199 B 199 GOOG 999 199
200 B 200 GOOG 999 200
201 B 201 GOOG 999 201
202 B 202 GOOG 999 202
203 B 203 GOOG 999 203
204 B 204 GOOG 999 204
205 B 205 GOOG 999 205
206 B 206 GOOG 999 206
207 B 207 GOOG 999 207
208 B 208 GOOG 999 208
209 B 209 GOOG 999 209
210 B 210 GOOG 999 210
211 B 211 GOOG 999 211
212 B 212 GOOG 999 212
213 B 213 GOOG 999 213
214 B 214 GOOG 999 214
215 B 215 GOOG 999 215
216 B 216 GOOG 999 216
217 B 217 GOOG 999 217
218 B 218 GOOG 999 218
219 B 219 GOOG 999 219
220 B 220 GOOG 999 220
221 B 221 GOOG 999 221
222 B 222 GOOG 999 222
223 B 223 GOOG 999 223
224 B 224 GOOG 999 224
225 B 225 GOOG 999 225
226 B 226 GOOG 999 226
227 B 227 GOOG 999 227
228 B 228 GOOG 999 228
229 B 229 GOOG 999 229
230 B 230 GOOG 999 230
231 B 231 GOOG 999 231
232 B 232 GOOG 999 232
233 B 233 GOOG 999 233
234 B 234 GOOG 999 234
235 B 235 GOOG 999 235
236 B 236 GOOG 999 236
237 B 237 GOOG 999 237
238 B 238 GOOG 999 238
239 B 239 GOOG 999 239
240 B 240 GOOG 999 240
241 B 241 GOOG 999 241
242 B 242 GOOG 999 242
243 B 243 GOOG 999 243
244 B 244 GOOG 999 244
245 B 245 GOOG 999 245
246 B 246 GOOG 999 246
247 B 247 GOOG 999 247
248 B 248 GOOG 999 248
249 B 249 GOOG 999 249
250 B 250 GOOG 999 250
251 B 251 GOOG 999 251
252 B 252 GOOG 999 252
253 B 253 GOOG 999 253
254 B 254 GOOG 999 254
255 B 255 GOOG 999 255
256 B 256 GOOG 999 256
257 B 257 GOOG 999 257
258 B 258 GOOG 999 258
259 B 259 GOOG 999 259
260 B 260 GOOG 999 260
261 B 261 GOOG 999 261
262 B 262 GOOG 999 262
263 B 263 GOOG 999 263
264 B 264 GOOG 999 264
265 B 265 GOOG 999 265
266 B 266 GOOG 999 266
267 B 267 GOOG 999 267
268 B 268 GOOG 999 268
269 B 269 GOOG 999 269
270 B 270 GOOG 999 270
271 B 271 GOOG 999 271
272 B 272 GOOG 999 272
273 B 273 GOOG 999 273
274 B 274 GOOG 999 274
275 B 275 GOOG 999 275
276 B 276 GOOG 999 276
277 B 277 GOOG 999 277
278 B 278 GOOG 999 278
279 B 279 GOOG 999 279
280 B 280 GOOG 999 280
281 B 281 GOOG 999 281
282 B 282 GOOG 999 282
283 B 283 GOOG 999 283
284 B 284 GOOG 999 284
285 B 285 GOOG 999 285
286 B 286 GOOG 999 286
287 B 287 GOOG 999 287
288 B 288 GOOG 999 288
289 B 289 GOOG 999 289
290 B 290 GOOG 999 290
291 B 291 GOOG 999 291
292 B 292 GOOG 999 292
293 B 293 GOOG 999 293
294 B 294 GOOG 999 294
295 B 295 GOOG 999 295
296 B 296 GOOG 999 296
297 B 297 GOOG 999 297
298 B 298 GOOG 999 298
299 B 299 GOOG 999 299
300 B 300 GOOG 999 300
301 B 301 GOOG 999 301
302 B 302 GOOG 999 302
303 B 303 GOOG 999 303
304 B 304 GOOG 999 304
305 B 305 GOOG 999 305
306 B 306 GOOG 999 306
307 B 307 GOOG 999 307
308 B 308 GOOG 999 308
309 B 309 GOOG 999 309
310 B 310 GOOG 999 310
311 B 311 GOOG 999 311
312 B 312 GOOG 999 312
313 B 313 GOOG 999 313
314 B 314 GOOG 999 314
315 B 315 GOOG 999 315
316 B 316 GOOG 999 316
317 B 317 GOOG 999 317
318 B 318 GOOG 999 318
319 B 319 GOOG 999 319
320 B 320 GOOG 999 320
321 B 321 GOOG 999 321
322 B 322 GOOG 999 322
323 B 323 GOOG 999 323
324 B 324 GOOG 999 324
325 B 325 GOOG 999 325
326 B 326 GOOG 999 326
327 B 327 GOOG 999 327
328 B 328 GOOG 999 328
329 B 329 GOOG 999 329
330 B 330 GOOG 999 330
331 B 331 GOOG 999 331
332 B 332 GOOG 999 332
333 B 333 GOOG 999 333
334 B 334 GOOG 999 334
335 B 335 GOOG 999 335
336 B 336 GOOG 999 336
337 B 337 GOOG 999 337
338 B 338 GOOG 999 338
339 B 339 GOOG 999 339
340 B 340 GOOG 999 340
341 B 341 GOOG 999 341
342 B 342 GOOG 999 342
343 B 343 GOOG 999 343
344 B 344 GOOG 999 344
345 B 345 GOOG 999 345
346 B 346 GOOG 999 346
347 B 347 GOOG 999 347
348 B 348 GOOG 999 348
349 B 349 GOOG 999 349
350 B 350 GOOG 999 350
351 B 351 GOOG 999 351
352 B 352 GOOG 999 352
353 B 353 GOOG 999 353
354 B 354 GOOG 999 354
355 B 355 GOOG 999 355
356 B 356 GOOG 999 356
357 B 357 GOOG 999 357
358 B 358 GOOG 999 358
359 B 359 GOOG 999 359
360 B 360 GOOG 999 360
361 B 361 GOOG 999 361
