tests/random-cancel.in
100
o
0 S 0 A 541 220
1 S 1 B 494 208
2 S 2 A 748 211
3 B 3 D 253 208
4 S 4 D 837 231
5 B 5 A 318 227
6 B 6 A 528 222
7 B 7 A 598 247
8 B 8 D 266 211
9 B 9 A 495 245
10 S 10 A 520 226
11 B 11 C 647 202
6 C 6
12 S 12 C 131 227
13 B 13 D 272 229
14 B 14 C 314 214
13 C 13
7 C 7
15 B 15 B 892 244
16 S 16 A 446 233
17 B 17 C 238 235
18 B 18 C 742 214
6 C 6
6 C 6
19 S 19 A 236 218
20 B 20 D 614 236
13 C 13
7 C 7
21 B 21 C 216 204
22 B 22 A 237 247
23 B 23 A 924 244
6 C 6
24 B 24 B 833 204
25 S 25 A 875 202
26 S 26 B 237 239
27 S 27 B 501 235
13 C 13
28 B 28 C 180 248
7 C 7
29 B 29 C 115 221
30 B 30 A 877 226
31 B 31 C 798 226
6 C 6
32 S 32 C 658 213
7 C 7
32 C 32
33 B 33 C 668 242
13 C 13
34 S 34 D 984 241
7 C 7
35 S 35 D 296 210
32 C 32
36 B 36 C 704 241
13 C 13
37 B 37 B 593 245
38 B 38 B 236 228
13 C 13
39 S 39 C 829 244
7 C 7
40 S 40 C 825 205
32 C 32
6 C 6
40 C 40
13 C 13
41 S 41 D 781 214
42 B 42 B 902 233
43 B 43 D 514 212
44 S 44 D 744 226
40 C 40
45 B 45 A 818 222
7 C 7
32 C 32
46 S 46 A 599 241
47 B 47 D 184 230
13 C 13
48 B 48 B 423 217
49 S 49 A 824 244
40 C 40
6 C 6
50 S 50 D 899 235
13 C 13
13 C 13
32 C 32
40 C 40
7 C 7
51 S 51 D 715 220
52 B 52 A 971 229
13 C 13
32 C 32
53 S 53 B 120 245
54 S 54 C 166 227
40 C 40
55 B 55 C 101 213
54 C 54
53 C 53
56 B 56 C 997 233
40 C 40
6 C 6
54 C 54
13 C 13
53 C 53
53 C 53
57 S 57 B 579 225
54 C 54
53 C 53
7 C 7
40 C 40
58 B 58 A 499 221
32 C 32
59 S 59 B 197 235
60 S 60 D 983 226
7 C 7
32 C 32
61 B 61 A 355 224
62 B 62 A 283 202
6 C 6
40 C 40
13 C 13
63 S 63 B 961 241
64 B 64 D 930 238
65 B 65 D 911 241
32 C 32
66 B 66 D 714 205
67 B 67 B 264 207
6 C 6
7 C 7
7 C 7
68 S 68 C 868 228
13 C 13
69 S 69 B 195 225
7 C 7
70 B 70 A 985 216
71 B 71 C 662 204
72 S 72 A 732 234
73 S 73 A 183 227
74 S 74 C 216 208
75 S 75 A 340 242
7 C 7
7 C 7
6 C 6
6 C 6
76 S 76 A 135 225
77 B 77 D 448 206
78 S 78 B 429 203
79 B 79 A 397 232
6 C 6
80 S 80 C 746 232
6 C 6
81 S 81 D 156 214
82 B 82 C 879 221
83 S 83 A 470 233
84 S 84 C 350 218
85 S 85 A 929 241
6 C 6
86 S 86 D 966 215
87 B 87 A 935 244
88 S 88 B 206 241
89 B 89 A 929 205
90 B 90 D 798 248
91 S 91 A 833 201
92 S 92 D 289 238
93 S 93 C 493 211
94 S 94 C 224 206
95 B 95 B 723 227
96 B 96 D 222 230
97 S 97 B 904 233
98 S 98 B 261 203
99 S 99 C 703 208
x
