tests/random-no-cancel.in
100
o
0 B 0 A 254 245
1 S 1 A 410 218
2 S 2 D 259 221
3 S 3 A 722 221
4 S 4 C 672 239
5 S 5 B 872 213
6 S 6 D 750 248
7 S 7 A 424 216
8 S 8 D 628 250
9 S 9 B 398 211
10 B 10 B 560 224
11 S 11 C 582 227
12 B 12 C 231 243
13 S 13 A 741 239
14 B 14 D 992 235
15 S 15 B 929 221
16 B 16 A 777 218
17 S 17 D 664 247
18 B 18 C 652 241
19 B 19 B 565 231
20 S 20 B 727 234
21 S 21 C 177 226
22 B 22 C 382 234
23 B 23 B 582 220
24 B 24 B 643 241
25 S 25 C 503 209
26 B 26 D 156 242
27 B 27 A 979 238
28 B 28 D 774 204
29 S 29 C 528 211
30 B 30 B 176 219
31 B 31 B 411 209
32 B 32 C 913 209
33 S 33 D 706 229
34 S 34 B 470 242
35 B 35 A 253 249
36 S 36 A 860 222
37 S 37 B 267 206
38 S 38 D 620 242
39 B 39 C 947 209
40 S 40 C 240 237
41 S 41 C 982 241
42 S 42 C 215 223
43 B 43 B 266 247
44 S 44 A 402 227
45 B 45 D 999 216
46 B 46 A 622 205
47 S 47 C 932 215
48 B 48 A 479 220
49 S 49 A 693 246
50 S 50 D 173 222
51 B 51 B 557 237
52 S 52 C 797 219
53 B 53 D 723 226
54 B 54 A 243 233
55 S 55 B 463 204
56 S 56 B 370 229
57 B 57 A 876 220
58 B 58 C 927 212
59 S 59 C 745 222
60 S 60 C 715 205
61 S 61 D 876 232
62 B 62 C 371 221
63 B 63 C 531 245
64 B 64 D 583 202
65 S 65 A 534 229
66 B 66 B 435 204
67 S 67 B 654 247
68 B 68 C 906 208
69 B 69 C 264 232
70 S 70 C 286 250
71 B 71 A 990 232
72 S 72 D 497 249
73 B 73 B 584 238
74 B 74 A 752 222
75 S 75 D 656 202
76 B 76 C 735 222
77 S 77 B 758 208
78 S 78 A 805 250
79 B 79 C 298 233
80 B 80 B 191 248
81 S 81 A 922 219
82 B 82 A 993 227
83 S 83 A 686 226
84 B 84 D 321 244
85 S 85 D 626 240
86 B 86 B 443 232
87 S 87 B 501 228
88 B 88 D 916 243
89 B 89 B 159 250
90 S 90 D 751 241
91 S 91 D 265 212
92 S 92 C 441 226
93 B 93 B 528 237
94 B 94 C 660 238
95 B 95 B 702 234
96 B 96 B 634 245
97 B 97 D 115 222
98 B 98 C 693 244
99 S 99 B 950 244
x
